Error before Pig is launched
----------------------------
ERROR 6000: 
<line 6, column 0> Output Location Validation Failed for: 'hdfs://localhost:9000/user/hadoop/output More info to follow:
Output directory hdfs://localhost:9000/user/hadoop/output already exists

org.apache.pig.backend.executionengine.ExecException: ERROR 1121: Python Error. Traceback (most recent call last):
  File "/src/week2/python/kmeans.py", line 121, in <module>
    main()
  File "/src/week2/python/kmeans.py", line 75, in main
    results = Q.runSingle()
<line 6, column 0> Output Location Validation Failed for: 'hdfs://localhost:9000/user/hadoop/output More info to follow:
Output directory hdfs://localhost:9000/user/hadoop/output already exists
	at org.apache.pig.newplan.logical.visitor.InputOutputFileValidatorVisitor.visit(InputOutputFileValidatorVisitor.java:95)
	at org.apache.pig.newplan.logical.relational.LOStore.accept(LOStore.java:66)
	at org.apache.pig.newplan.DepthFirstWalker.depthFirst(DepthFirstWalker.java:64)
	at org.apache.pig.newplan.DepthFirstWalker.depthFirst(DepthFirstWalker.java:66)
	at org.apache.pig.newplan.DepthFirstWalker.depthFirst(DepthFirstWalker.java:66)
	at org.apache.pig.newplan.DepthFirstWalker.depthFirst(DepthFirstWalker.java:66)
	at org.apache.pig.newplan.DepthFirstWalker.depthFirst(DepthFirstWalker.java:66)
	at org.apache.pig.newplan.DepthFirstWalker.walk(DepthFirstWalker.java:53)
	at org.apache.pig.newplan.PlanVisitor.visit(PlanVisitor.java:52)
	at org.apache.pig.newplan.logical.relational.LogicalPlan.validate(LogicalPlan.java:212)
	at org.apache.pig.PigServer$Graph.compile(PigServer.java:1851)
	at org.apache.pig.PigServer$Graph.access$300(PigServer.java:1527)
	at org.apache.pig.PigServer.execute(PigServer.java:1440)
	at org.apache.pig.PigServer.executeBatch(PigServer.java:488)
	at org.apache.pig.PigServer.executeBatch(PigServer.java:471)
	at org.apache.pig.tools.grunt.GruntParser.executeBatch(GruntParser.java:172)
	at org.apache.pig.tools.grunt.GruntParser.parseStopOnError(GruntParser.java:235)
	at org.apache.pig.scripting.BoundScript.exec(BoundScript.java:277)
	at org.apache.pig.scripting.BoundScript.runSingle(BoundScript.java:101)
	at org.apache.pig.scripting.BoundScript.runSingle(BoundScript.java:77)
	at sun.reflect.NativeMethodAccessorImpl.invoke0(Native Method)
	at sun.reflect.NativeMethodAccessorImpl.invoke(NativeMethodAccessorImpl.java:62)
	at sun.reflect.DelegatingMethodAccessorImpl.invoke(DelegatingMethodAccessorImpl.java:43)
	at java.lang.reflect.Method.invoke(Method.java:498)

org.apache.pig.impl.plan.VisitorException: org.apache.pig.impl.plan.VisitorException: ERROR 6000: 
<line 6, column 0> Output Location Validation Failed for: 'hdfs://localhost:9000/user/hadoop/output More info to follow:
Output directory hdfs://localhost:9000/user/hadoop/output already exists

	at org.apache.pig.scripting.jython.JythonScriptEngine$Interpreter.execfile(JythonScriptEngine.java:249)
	at org.apache.pig.scripting.jython.JythonScriptEngine.load(JythonScriptEngine.java:440)
	at org.apache.pig.scripting.jython.JythonScriptEngine.main(JythonScriptEngine.java:424)
	at org.apache.pig.scripting.ScriptEngine.run(ScriptEngine.java:310)
	at org.apache.pig.Main.runEmbeddedScript(Main.java:1079)
	at org.apache.pig.Main.run(Main.java:584)
	at org.apache.pig.Main.main(Main.java:176)
	at sun.reflect.NativeMethodAccessorImpl.invoke0(Native Method)
	at sun.reflect.NativeMethodAccessorImpl.invoke(NativeMethodAccessorImpl.java:62)
	at sun.reflect.DelegatingMethodAccessorImpl.invoke(DelegatingMethodAccessorImpl.java:43)
	at java.lang.reflect.Method.invoke(Method.java:498)
	at org.apache.hadoop.util.RunJar.run(RunJar.java:221)
	at org.apache.hadoop.util.RunJar.main(RunJar.java:136)
Caused by: Traceback (most recent call last):
  File "/src/week2/python/kmeans.py", line 121, in <module>
    main()
  File "/src/week2/python/kmeans.py", line 75, in main
    results = Q.runSingle()
<line 6, column 0> Output Location Validation Failed for: 'hdfs://localhost:9000/user/hadoop/output More info to follow:
Output directory hdfs://localhost:9000/user/hadoop/output already exists
	at org.apache.pig.newplan.logical.visitor.InputOutputFileValidatorVisitor.visit(InputOutputFileValidatorVisitor.java:95)
	at org.apache.pig.newplan.logical.relational.LOStore.accept(LOStore.java:66)
	at org.apache.pig.newplan.DepthFirstWalker.depthFirst(DepthFirstWalker.java:64)
	at org.apache.pig.newplan.DepthFirstWalker.depthFirst(DepthFirstWalker.java:66)
	at org.apache.pig.newplan.DepthFirstWalker.depthFirst(DepthFirstWalker.java:66)
	at org.apache.pig.newplan.DepthFirstWalker.depthFirst(DepthFirstWalker.java:66)
	at org.apache.pig.newplan.DepthFirstWalker.depthFirst(DepthFirstWalker.java:66)
	at org.apache.pig.newplan.DepthFirstWalker.walk(DepthFirstWalker.java:53)
	at org.apache.pig.newplan.PlanVisitor.visit(PlanVisitor.java:52)
	at org.apache.pig.newplan.logical.relational.LogicalPlan.validate(LogicalPlan.java:212)
	at org.apache.pig.PigServer$Graph.compile(PigServer.java:1851)
	at org.apache.pig.PigServer$Graph.access$300(PigServer.java:1527)
	at org.apache.pig.PigServer.execute(PigServer.java:1440)
	at org.apache.pig.PigServer.executeBatch(PigServer.java:488)
	at org.apache.pig.PigServer.executeBatch(PigServer.java:471)
	at org.apache.pig.tools.grunt.GruntParser.executeBatch(GruntParser.java:172)
	at org.apache.pig.tools.grunt.GruntParser.parseStopOnError(GruntParser.java:235)
	at org.apache.pig.scripting.BoundScript.exec(BoundScript.java:277)
	at org.apache.pig.scripting.BoundScript.runSingle(BoundScript.java:101)
	at org.apache.pig.scripting.BoundScript.runSingle(BoundScript.java:77)
	at sun.reflect.NativeMethodAccessorImpl.invoke0(Native Method)
	at sun.reflect.NativeMethodAccessorImpl.invoke(NativeMethodAccessorImpl.java:62)
	at sun.reflect.DelegatingMethodAccessorImpl.invoke(DelegatingMethodAccessorImpl.java:43)
	at java.lang.reflect.Method.invoke(Method.java:498)

org.apache.pig.impl.plan.VisitorException: org.apache.pig.impl.plan.VisitorException: ERROR 6000: 
<line 6, column 0> Output Location Validation Failed for: 'hdfs://localhost:9000/user/hadoop/output More info to follow:
Output directory hdfs://localhost:9000/user/hadoop/output already exists

	at org.python.core.Py.JavaError(Py.java:546)
	at org.python.core.Py.JavaError(Py.java:537)
	at org.python.core.PyReflectedFunction.__call__(PyReflectedFunction.java:188)
	at org.python.core.PyReflectedFunction.__call__(PyReflectedFunction.java:204)
	at org.python.core.PyObject.__call__(PyObject.java:461)
	at org.python.core.PyObject.__call__(PyObject.java:465)
	at org.python.core.PyMethod.__call__(PyMethod.java:126)
	at org.python.pycode._pyx4.main$3(/src/week2/python/kmeans.py:118)
	at org.python.pycode._pyx4.call_function(/src/week2/python/kmeans.py)
	at org.python.core.PyTableCode.call(PyTableCode.java:167)
	at org.python.core.PyBaseCode.call(PyBaseCode.java:124)
	at org.python.core.PyFunction.__call__(PyFunction.java:403)
	at org.python.pycode._pyx4.f$0(/src/week2/python/kmeans.py:121)
	at org.python.pycode._pyx4.call_function(/src/week2/python/kmeans.py)
	at org.python.core.PyTableCode.call(PyTableCode.java:167)
	at org.python.core.PyCode.call(PyCode.java:18)
	at org.python.core.Py.runCode(Py.java:1386)
	at org.python.util.PythonInterpreter.execfile(PythonInterpreter.java:296)
	at org.apache.pig.scripting.jython.JythonScriptEngine$Interpreter.execfile(JythonScriptEngine.java:217)
	... 12 more
Caused by: org.apache.pig.impl.plan.VisitorException: ERROR 6000: 
<line 6, column 0> Output Location Validation Failed for: 'hdfs://localhost:9000/user/hadoop/output More info to follow:
Output directory hdfs://localhost:9000/user/hadoop/output already exists
	at org.apache.pig.newplan.logical.visitor.InputOutputFileValidatorVisitor.visit(InputOutputFileValidatorVisitor.java:95)
	at org.apache.pig.newplan.logical.relational.LOStore.accept(LOStore.java:66)
	at org.apache.pig.newplan.DepthFirstWalker.depthFirst(DepthFirstWalker.java:64)
	at org.apache.pig.newplan.DepthFirstWalker.depthFirst(DepthFirstWalker.java:66)
	at org.apache.pig.newplan.DepthFirstWalker.depthFirst(DepthFirstWalker.java:66)
	at org.apache.pig.newplan.DepthFirstWalker.depthFirst(DepthFirstWalker.java:66)
	at org.apache.pig.newplan.DepthFirstWalker.depthFirst(DepthFirstWalker.java:66)
	at org.apache.pig.newplan.DepthFirstWalker.walk(DepthFirstWalker.java:53)
	at org.apache.pig.newplan.PlanVisitor.visit(PlanVisitor.java:52)
	at org.apache.pig.newplan.logical.relational.LogicalPlan.validate(LogicalPlan.java:212)
	at org.apache.pig.PigServer$Graph.compile(PigServer.java:1851)
	at org.apache.pig.PigServer$Graph.access$300(PigServer.java:1527)
	at org.apache.pig.PigServer.execute(PigServer.java:1440)
	at org.apache.pig.PigServer.executeBatch(PigServer.java:488)
	at org.apache.pig.PigServer.executeBatch(PigServer.java:471)
	at org.apache.pig.tools.grunt.GruntParser.executeBatch(GruntParser.java:172)
	at org.apache.pig.tools.grunt.GruntParser.parseStopOnError(GruntParser.java:235)
	at org.apache.pig.scripting.BoundScript.exec(BoundScript.java:277)
	at org.apache.pig.scripting.BoundScript.runSingle(BoundScript.java:101)
	at org.apache.pig.scripting.BoundScript.runSingle(BoundScript.java:77)
	at sun.reflect.NativeMethodAccessorImpl.invoke0(Native Method)
	at sun.reflect.NativeMethodAccessorImpl.invoke(NativeMethodAccessorImpl.java:62)
	at sun.reflect.DelegatingMethodAccessorImpl.invoke(DelegatingMethodAccessorImpl.java:43)
	at java.lang.reflect.Method.invoke(Method.java:498)
	at org.python.core.PyReflectedFunction.__call__(PyReflectedFunction.java:186)
	... 28 more
Caused by: org.apache.hadoop.mapred.FileAlreadyExistsException: Output directory hdfs://localhost:9000/user/hadoop/output already exists
	at org.apache.hadoop.mapreduce.lib.output.FileOutputFormat.checkOutputSpecs(FileOutputFormat.java:146)
	at org.apache.pig.newplan.logical.visitor.InputOutputFileValidatorVisitor.visit(InputOutputFileValidatorVisitor.java:69)
	... 52 more
================================================================================
